<robot name = "robot">
    <link name="0">
        <inertial>
            <origin xyz="0 0 0.19370494369065094" rpy="0 0 0"/>
            <mass value="1" />
            <inertia ixx="100" ixy="0" ixz="0" iyy="100" iyz="0" izz="100" />
        </inertial>
        <visual>
            <origin xyz="0 0 0.19370494369065094" rpy="0 0 0"/>
            <geometry>
                <box size="0.10213392806589053 0.49435482570663103 0.3874098873813019" />
            </geometry>
            <material name="Green">
                <color rgba="0 1.0 0 1.0"/>
            </material>
        </visual>
        <collision>
            <origin xyz="0 0 0.19370494369065094" rpy="0 0 0"/>
            <geometry>
                <box size="0.10213392806589053 0.49435482570663103 0.3874098873813019" />
            </geometry>
        </collision>
    </link>
    <joint name="0_1" type="revolute">
       <parent link="0"/>
       <child  link="1"/>
       <origin rpy="0 0 0" xyz="0 0 0.3874098873813019" />
     <axis xyz="0 1 1"/>
       <limit effort="0.0" lower="-3.14159" upper="3.14159" velocity="0.0"/>
    </joint>
    <link name="1">
        <inertial>
            <origin xyz="0 0 0.2542059129603427" rpy="0 0 0"/>
            <mass value="1" />
            <inertia ixx="100" ixy="0" ixz="0" iyy="100" iyz="0" izz="100" />
        </inertial>
        <visual>
            <origin xyz="0 0 0.2542059129603427" rpy="0 0 0"/>
            <geometry>
                <box size="0.43119556264339054 0.4776288885118417 0.5084118259206853" />
            </geometry>
            <material name="Green">
                <color rgba="0 1.0 0 1.0"/>
            </material>
        </visual>
        <collision>
            <origin xyz="0 0 0.2542059129603427" rpy="0 0 0"/>
            <geometry>
                <box size="0.43119556264339054 0.4776288885118417 0.5084118259206853" />
            </geometry>
        </collision>
    </link>
    <joint name="1_2" type="revolute">
       <parent link="1"/>
       <child  link="2"/>
       <origin rpy="0 0 0" xyz="-0.21559778132169527 0 0.2542059129603427" />
     <axis xyz="1 1 0"/>
       <limit effort="0.0" lower="-3.14159" upper="3.14159" velocity="0.0"/>
    </joint>
    <link name="2">
        <inertial>
            <origin xyz="-0.23724521527901354 0 0" rpy="0 0 0"/>
            <mass value="1" />
            <inertia ixx="100" ixy="0" ixz="0" iyy="100" iyz="0" izz="100" />
        </inertial>
        <visual>
            <origin xyz="-0.23724521527901354 0 0" rpy="0 0 0"/>
            <geometry>
                <box size="0.4744904305580271 0.5309517976924946 0.44526770575170205" />
            </geometry>
            <material name="Green">
                <color rgba="0 1.0 0 1.0"/>
            </material>
        </visual>
        <collision>
            <origin xyz="-0.23724521527901354 0 0" rpy="0 0 0"/>
            <geometry>
                <box size="0.4744904305580271 0.5309517976924946 0.44526770575170205" />
            </geometry>
        </collision>
    </link>
    <joint name="1_3" type="revolute">
       <parent link="1"/>
       <child  link="3"/>
       <origin rpy="0 0 0" xyz="0.21559778132169527 0 0.2542059129603427" />
     <axis xyz="1 1 0"/>
       <limit effort="0.0" lower="-3.14159" upper="3.14159" velocity="0.0"/>
    </joint>
    <link name="3">
        <inertial>
            <origin xyz="0.2066284630392658 0 0" rpy="0 0 0"/>
            <mass value="1" />
            <inertia ixx="100" ixy="0" ixz="0" iyy="100" iyz="0" izz="100" />
        </inertial>
        <visual>
            <origin xyz="0.2066284630392658 0 0" rpy="0 0 0"/>
            <geometry>
                <box size="0.4132569260785316 0.22942099969040877 0.46518265145845283" />
            </geometry>
            <material name="Green">
                <color rgba="0 1.0 0 1.0"/>
            </material>
        </visual>
        <collision>
            <origin xyz="0.2066284630392658 0 0" rpy="0 0 0"/>
            <geometry>
                <box size="0.4132569260785316 0.22942099969040877 0.46518265145845283" />
            </geometry>
        </collision>
    </link>
    <joint name="1_4" type="revolute">
       <parent link="1"/>
       <child  link="4"/>
       <origin rpy="0 0 0" xyz="0 -0.23881444425592085 0.2542059129603427" />
     <axis xyz="1 1 0"/>
       <limit effort="0.0" lower="-3.14159" upper="3.14159" velocity="0.0"/>
    </joint>
    <link name="4">
        <inertial>
            <origin xyz="0 -0.2729342635569946 0" rpy="0 0 0"/>
            <mass value="1" />
            <inertia ixx="100" ixy="0" ixz="0" iyy="100" iyz="0" izz="100" />
        </inertial>
        <visual>
            <origin xyz="0 -0.2729342635569946 0" rpy="0 0 0"/>
            <geometry>
                <box size="0.2600090848106854 0.5458685271139893 0.21783281919563882" />
            </geometry>
            <material name="Green">
                <color rgba="0 1.0 0 1.0"/>
            </material>
        </visual>
        <collision>
            <origin xyz="0 -0.2729342635569946 0" rpy="0 0 0"/>
            <geometry>
                <box size="0.2600090848106854 0.5458685271139893 0.21783281919563882" />
            </geometry>
        </collision>
    </link>
    <joint name="0_5" type="revolute">
       <parent link="0"/>
       <child  link="5"/>
       <origin rpy="0 0 0" xyz="0.051066964032945264 0.0 0.19370494369065094" />
     <axis xyz="1 1 0"/>
       <limit effort="0.0" lower="-3.14159" upper="3.14159" velocity="0.0"/>
    </joint>
    <link name="5">
        <inertial>
            <origin xyz="0.09118046737525999 0 0" rpy="0 0 0"/>
            <mass value="1" />
            <inertia ixx="100" ixy="0" ixz="0" iyy="100" iyz="0" izz="100" />
        </inertial>
        <visual>
            <origin xyz="0.09118046737525999 0 0" rpy="0 0 0"/>
            <geometry>
                <box size="0.18236093475051998 0.3556007491033587 0.2535137724636377" />
            </geometry>
            <material name="Green">
                <color rgba="0 1.0 0 1.0"/>
            </material>
        </visual>
        <collision>
            <origin xyz="0.09118046737525999 0 0" rpy="0 0 0"/>
            <geometry>
                <box size="0.18236093475051998 0.3556007491033587 0.2535137724636377" />
            </geometry>
        </collision>
    </link>
</robot>