<robot name = "robot">
    <link name="0">
        <inertial>
            <origin xyz="0 0 0.18407866689433483" rpy="0 0 0"/>
            <mass value="1" />
            <inertia ixx="100" ixy="0" ixz="0" iyy="100" iyz="0" izz="100" />
        </inertial>
        <visual>
            <origin xyz="0 0 0.18407866689433483" rpy="0 0 0"/>
            <geometry>
                <box size="0.41050246577154326 0.13322161966533633 0.36815733378866966" />
            </geometry>
            <material name="Green">
                <color rgba="0 1.0 0 1.0"/>
            </material>
        </visual>
        <collision>
            <origin xyz="0 0 0.18407866689433483" rpy="0 0 0"/>
            <geometry>
                <box size="0.41050246577154326 0.13322161966533633 0.36815733378866966" />
            </geometry>
        </collision>
    </link>
    <joint name="0_1" type="revolute">
       <parent link="0"/>
       <child  link="1"/>
       <origin rpy="0 0 0" xyz="0 0 0.36815733378866966" />
     <axis xyz="0 1 1"/>
       <limit effort="0.0" lower="-3.14159" upper="3.14159" velocity="0.0"/>
    </joint>
    <link name="1">
        <inertial>
            <origin xyz="0 0 0.2749465844884344" rpy="0 0 0"/>
            <mass value="1" />
            <inertia ixx="100" ixy="0" ixz="0" iyy="100" iyz="0" izz="100" />
        </inertial>
        <visual>
            <origin xyz="0 0 0.2749465844884344" rpy="0 0 0"/>
            <geometry>
                <box size="0.13631467126669297 0.33736190192116045 0.5498931689768688" />
            </geometry>
            <material name="Cyan">
                <color rgba="0 1.0 1.0 1.0"/>
            </material>
        </visual>
        <collision>
            <origin xyz="0 0 0.2749465844884344" rpy="0 0 0"/>
            <geometry>
                <box size="0.13631467126669297 0.33736190192116045 0.5498931689768688" />
            </geometry>
        </collision>
    </link>
    <joint name="1_2" type="revolute">
       <parent link="1"/>
       <child  link="2"/>
       <origin rpy="0 0 0" xyz="0 -0.16868095096058022 0.2749465844884344" />
     <axis xyz="1 1 0"/>
       <limit effort="0.0" lower="-3.14159" upper="3.14159" velocity="0.0"/>
    </joint>
    <link name="2">
        <inertial>
            <origin xyz="0 -0.206917886213839 0" rpy="0 0 0"/>
            <mass value="1" />
            <inertia ixx="100" ixy="0" ixz="0" iyy="100" iyz="0" izz="100" />
        </inertial>
        <visual>
            <origin xyz="0 -0.206917886213839 0" rpy="0 0 0"/>
            <geometry>
                <box size="0.46126783150926975 0.413835772427678 0.47813243636196223" />
            </geometry>
            <material name="Green">
                <color rgba="0 1.0 0 1.0"/>
            </material>
        </visual>
        <collision>
            <origin xyz="0 -0.206917886213839 0" rpy="0 0 0"/>
            <geometry>
                <box size="0.46126783150926975 0.413835772427678 0.47813243636196223" />
            </geometry>
        </collision>
    </link>
    <joint name="1_3" type="revolute">
       <parent link="1"/>
       <child  link="3"/>
       <origin rpy="0 0 0" xyz="0 0.16868095096058022 0.2749465844884344" />
     <axis xyz="1 1 0"/>
       <limit effort="0.0" lower="-3.14159" upper="3.14159" velocity="0.0"/>
    </joint>
    <link name="3">
        <inertial>
            <origin xyz="0 0.18869818414883283 0" rpy="0 0 0"/>
            <mass value="1" />
            <inertia ixx="100" ixy="0" ixz="0" iyy="100" iyz="0" izz="100" />
        </inertial>
        <visual>
            <origin xyz="0 0.18869818414883283 0" rpy="0 0 0"/>
            <geometry>
                <box size="0.5716871917549639 0.37739636829766565 0.1676215956223789" />
            </geometry>
            <material name="Cyan">
                <color rgba="0 1.0 1.0 1.0"/>
            </material>
        </visual>
        <collision>
            <origin xyz="0 0.18869818414883283 0" rpy="0 0 0"/>
            <geometry>
                <box size="0.5716871917549639 0.37739636829766565 0.1676215956223789" />
            </geometry>
        </collision>
    </link>
    <joint name="0_4" type="revolute">
       <parent link="0"/>
       <child  link="4"/>
       <origin rpy="0 0 0" xyz="-0.20525123288577163 0 0.18407866689433483" />
     <axis xyz="1 1 0"/>
       <limit effort="0.0" lower="-3.14159" upper="3.14159" velocity="0.0"/>
    </joint>
    <link name="4">
        <inertial>
            <origin xyz="-0.14226988029165544 0 0" rpy="0 0 0"/>
            <mass value="1" />
            <inertia ixx="100" ixy="0" ixz="0" iyy="100" iyz="0" izz="100" />
        </inertial>
        <visual>
            <origin xyz="-0.14226988029165544 0 0" rpy="0 0 0"/>
            <geometry>
                <box size="0.2845397605833109 0.12550490243431497 0.25234425731467436" />
            </geometry>
            <material name="Cyan">
                <color rgba="0 1.0 1.0 1.0"/>
            </material>
        </visual>
        <collision>
            <origin xyz="-0.14226988029165544 0 0" rpy="0 0 0"/>
            <geometry>
                <box size="0.2845397605833109 0.12550490243431497 0.25234425731467436" />
            </geometry>
        </collision>
    </link>
    <joint name="2_5" type="revolute">
       <parent link="2"/>
       <child  link="5"/>
       <origin rpy="0 0 0" xyz="0 -0.206917886213839 0.2390662181809811" />
     <axis xyz="0 1 1"/>
       <limit effort="0.0" lower="-3.14159" upper="3.14159" velocity="0.0"/>
    </joint>
    <link name="5">
        <inertial>
            <origin xyz="0 0 0.10863429529849837" rpy="0 0 0"/>
            <mass value="1" />
            <inertia ixx="100" ixy="0" ixz="0" iyy="100" iyz="0" izz="100" />
        </inertial>
        <visual>
            <origin xyz="0 0 0.10863429529849837" rpy="0 0 0"/>
            <geometry>
                <box size="0.41845349068135385 0.3821070566794259 0.21726859059699674" />
            </geometry>
            <material name="Cyan">
                <color rgba="0 1.0 1.0 1.0"/>
            </material>
        </visual>
        <collision>
            <origin xyz="0 0 0.10863429529849837" rpy="0 0 0"/>
            <geometry>
                <box size="0.41845349068135385 0.3821070566794259 0.21726859059699674" />
            </geometry>
        </collision>
    </link>
    <joint name="3_6" type="revolute">
       <parent link="3"/>
       <child  link="6"/>
       <origin rpy="0 0 0" xyz="0 0.37739636829766565 0" />
     <axis xyz="1 1 0"/>
       <limit effort="0.0" lower="-3.14159" upper="3.14159" velocity="0.0"/>
    </joint>
    <link name="6">
        <inertial>
            <origin xyz="0 0.23400290663676132 0" rpy="0 0 0"/>
            <mass value="1" />
            <inertia ixx="100" ixy="0" ixz="0" iyy="100" iyz="0" izz="100" />
        </inertial>
        <visual>
            <origin xyz="0 0.23400290663676132 0" rpy="0 0 0"/>
            <geometry>
                <box size="0.5704831865157391 0.46800581327352264 0.4296668775594289" />
            </geometry>
            <material name="Cyan">
                <color rgba="0 1.0 1.0 1.0"/>
            </material>
        </visual>
        <collision>
            <origin xyz="0 0.23400290663676132 0" rpy="0 0 0"/>
            <geometry>
                <box size="0.5704831865157391 0.46800581327352264 0.4296668775594289" />
            </geometry>
        </collision>
    </link>
    <joint name="3_7" type="revolute">
       <parent link="3"/>
       <child  link="7"/>
       <origin rpy="0 0 0" xyz="0.2858435958774819 0.18869818414883283 0" />
     <axis xyz="1 1 0"/>
       <limit effort="0.0" lower="-3.14159" upper="3.14159" velocity="0.0"/>
    </joint>
    <link name="7">
        <inertial>
            <origin xyz="0.23336490604210708 0 0" rpy="0 0 0"/>
            <mass value="1" />
            <inertia ixx="100" ixy="0" ixz="0" iyy="100" iyz="0" izz="100" />
        </inertial>
        <visual>
            <origin xyz="0.23336490604210708 0 0" rpy="0 0 0"/>
            <geometry>
                <box size="0.46672981208421416 0.4988752461330579 0.5520602032496837" />
            </geometry>
            <material name="Cyan">
                <color rgba="0 1.0 1.0 1.0"/>
            </material>
        </visual>
        <collision>
            <origin xyz="0.23336490604210708 0 0" rpy="0 0 0"/>
            <geometry>
                <box size="0.46672981208421416 0.4988752461330579 0.5520602032496837" />
            </geometry>
        </collision>
    </link>
    <joint name="5_8" type="revolute">
       <parent link="5"/>
       <child  link="8"/>
       <origin rpy="0 0 0" xyz="0 0 0.21726859059699666" />
     <axis xyz="0 1 1"/>
       <limit effort="0.0" lower="-3.14159" upper="3.14159" velocity="0.0"/>
    </joint>
    <link name="8">
        <inertial>
            <origin xyz="0 0 0.11656553891631725" rpy="0 0 0"/>
            <mass value="1" />
            <inertia ixx="100" ixy="0" ixz="0" iyy="100" iyz="0" izz="100" />
        </inertial>
        <visual>
            <origin xyz="0 0 0.11656553891631725" rpy="0 0 0"/>
            <geometry>
                <box size="0.22251377204852232 0.20855468529584234 0.2331310778326345" />
            </geometry>
            <material name="Cyan">
                <color rgba="0 1.0 1.0 1.0"/>
            </material>
        </visual>
        <collision>
            <origin xyz="0 0 0.11656553891631725" rpy="0 0 0"/>
            <geometry>
                <box size="0.22251377204852232 0.20855468529584234 0.2331310778326345" />
            </geometry>
        </collision>
    </link>
    <joint name="2_9" type="revolute">
       <parent link="2"/>
       <child  link="9"/>
       <origin rpy="0 0 0" xyz="0.23063391575463488 -0.206917886213839 0" />
     <axis xyz="1 1 0"/>
       <limit effort="0.0" lower="-3.14159" upper="3.14159" velocity="0.0"/>
    </joint>
    <link name="9">
        <inertial>
            <origin xyz="0.07350095158809235 0 0" rpy="0 0 0"/>
            <mass value="1" />
            <inertia ixx="100" ixy="0" ixz="0" iyy="100" iyz="0" izz="100" />
        </inertial>
        <visual>
            <origin xyz="0.07350095158809235 0 0" rpy="0 0 0"/>
            <geometry>
                <box size="0.1470019031761847 0.15111863940521467 0.32945794878770085" />
            </geometry>
            <material name="Green">
                <color rgba="0 1.0 0 1.0"/>
            </material>
        </visual>
        <collision>
            <origin xyz="0.07350095158809235 0 0" rpy="0 0 0"/>
            <geometry>
                <box size="0.1470019031761847 0.15111863940521467 0.32945794878770085" />
            </geometry>
        </collision>
    </link>
</robot>