<robot name = "robot">
    <link name="0">
        <inertial>
            <origin xyz="0 0 0.2647509056142045" rpy="0 0 0"/>
            <mass value="1" />
            <inertia ixx="100" ixy="0" ixz="0" iyy="100" iyz="0" izz="100" />
        </inertial>
        <visual>
            <origin xyz="0 0 0.2647509056142045" rpy="0 0 0"/>
            <geometry>
                <box size="0.5171144077530784 0.5269961621900432 0.529501811228409" />
            </geometry>
            <material name="Cyan">
                <color rgba="0 1.0 1.0 1.0"/>
            </material>
        </visual>
        <collision>
            <origin xyz="0 0 0.2647509056142045" rpy="0 0 0"/>
            <geometry>
                <box size="0.5171144077530784 0.5269961621900432 0.529501811228409" />
            </geometry>
        </collision>
    </link>
    <joint name="0_1" type="revolute">
       <parent link="0"/>
       <child  link="1"/>
       <origin rpy="0 0 0" xyz="0 0 0.529501811228409" />
     <axis xyz="0 1 1"/>
       <limit effort="0.0" lower="-3.14159" upper="3.14159" velocity="0.0"/>
    </joint>
    <link name="1">
        <inertial>
            <origin xyz="0 0 0.25689203679842043" rpy="0 0 0"/>
            <mass value="1" />
            <inertia ixx="100" ixy="0" ixz="0" iyy="100" iyz="0" izz="100" />
        </inertial>
        <visual>
            <origin xyz="0 0 0.25689203679842043" rpy="0 0 0"/>
            <geometry>
                <box size="0.4196850013340909 0.5846164940127191 0.5137840735968409" />
            </geometry>
            <material name="Green">
                <color rgba="0 1.0 0 1.0"/>
            </material>
        </visual>
        <collision>
            <origin xyz="0 0 0.25689203679842043" rpy="0 0 0"/>
            <geometry>
                <box size="0.4196850013340909 0.5846164940127191 0.5137840735968409" />
            </geometry>
        </collision>
    </link>
    <joint name="1_3" type="revolute">
       <parent link="1"/>
       <child  link="3"/>
       <origin rpy="0 0 0" xyz="0.20984250066704546 0 0.25689203679842043" />
     <axis xyz="1 1 0"/>
       <limit effort="0.0" lower="-3.14159" upper="3.14159" velocity="0.0"/>
    </joint>
    <link name="3">
        <inertial>
            <origin xyz="0.277912802664224 0 0" rpy="0 0 0"/>
            <mass value="1" />
            <inertia ixx="100" ixy="0" ixz="0" iyy="100" iyz="0" izz="100" />
        </inertial>
        <visual>
            <origin xyz="0.277912802664224 0 0" rpy="0 0 0"/>
            <geometry>
                <box size="0.555825605328448 0.44635946346205213 0.37038113007024054" />
            </geometry>
            <material name="Green">
                <color rgba="0 1.0 0 1.0"/>
            </material>
        </visual>
        <collision>
            <origin xyz="0.277912802664224 0 0" rpy="0 0 0"/>
            <geometry>
                <box size="0.555825605328448 0.44635946346205213 0.37038113007024054" />
            </geometry>
        </collision>
    </link>
    <joint name="0_4" type="revolute">
       <parent link="0"/>
       <child  link="4"/>
       <origin rpy="0 0 0" xyz="0.2585572038765392 0 0.2647509056142045" />
     <axis xyz="1 1 0"/>
       <limit effort="0.0" lower="-3.14159" upper="3.14159" velocity="0.0"/>
    </joint>
    <link name="4">
        <inertial>
            <origin xyz="0.1811015941482943 0 0" rpy="0 0 0"/>
            <mass value="1" />
            <inertia ixx="100" ixy="0" ixz="0" iyy="100" iyz="0" izz="100" />
        </inertial>
        <visual>
            <origin xyz="0.1811015941482943 0 0" rpy="0 0 0"/>
            <geometry>
                <box size="0.3622031882965886 0.4852768074347569 0.40978343201940093" />
            </geometry>
            <material name="Green">
                <color rgba="0 1.0 0 1.0"/>
            </material>
        </visual>
        <collision>
            <origin xyz="0.1811015941482943 0 0" rpy="0 0 0"/>
            <geometry>
                <box size="0.3622031882965886 0.4852768074347569 0.40978343201940093" />
            </geometry>
        </collision>
    </link>
    <joint name="4_5" type="revolute">
       <parent link="4"/>
       <child  link="5"/>
       <origin rpy="0 0 0" xyz="0.3622031882965886 0 0" />
     <axis xyz="1 1 0"/>
       <limit effort="0.0" lower="-3.14159" upper="3.14159" velocity="0.0"/>
    </joint>
    <link name="5">
        <inertial>
            <origin xyz="0.26685430558978046 0 0" rpy="0 0 0"/>
            <mass value="1" />
            <inertia ixx="100" ixy="0" ixz="0" iyy="100" iyz="0" izz="100" />
        </inertial>
        <visual>
            <origin xyz="0.26685430558978046 0 0" rpy="0 0 0"/>
            <geometry>
                <box size="0.5337086111795609 0.560334173705149 0.22696060617417937" />
            </geometry>
            <material name="Cyan">
                <color rgba="0 1.0 1.0 1.0"/>
            </material>
        </visual>
        <collision>
            <origin xyz="0.26685430558978046 0 0" rpy="0 0 0"/>
            <geometry>
                <box size="0.5337086111795609 0.560334173705149 0.22696060617417937" />
            </geometry>
        </collision>
    </link>
    <joint name="0_6" type="revolute">
       <parent link="0"/>
       <child  link="6"/>
       <origin rpy="0 0 0" xyz="0 -0.2634980810950216 0.2647509056142045" />
     <axis xyz="1 1 0"/>
       <limit effort="0.0" lower="-3.14159" upper="3.14159" velocity="0.0"/>
    </joint>
    <link name="6">
        <inertial>
            <origin xyz="0 -0.18215404095705856 0" rpy="0 0 0"/>
            <mass value="1" />
            <inertia ixx="100" ixy="0" ixz="0" iyy="100" iyz="0" izz="100" />
        </inertial>
        <visual>
            <origin xyz="0 -0.18215404095705856 0" rpy="0 0 0"/>
            <geometry>
                <box size="0.42010875397710656 0.3643080819141171 0.231710650051855" />
            </geometry>
            <material name="Green">
                <color rgba="0 1.0 0 1.0"/>
            </material>
        </visual>
        <collision>
            <origin xyz="0 -0.18215404095705856 0" rpy="0 0 0"/>
            <geometry>
                <box size="0.42010875397710656 0.3643080819141171 0.231710650051855" />
            </geometry>
        </collision>
    </link>
    <joint name="5_9" type="revolute">
       <parent link="5"/>
       <child  link="9"/>
       <origin rpy="0 0 0" xyz="0.2668543055897805 0 0.11348030308708967" />
     <axis xyz="0 1 1"/>
       <limit effort="0.0" lower="-3.14159" upper="3.14159" velocity="0.0"/>
    </joint>
    <link name="9">
        <inertial>
            <origin xyz="0 0 0.10908458525253449" rpy="0 0 0"/>
            <mass value="1" />
            <inertia ixx="100" ixy="0" ixz="0" iyy="100" iyz="0" izz="100" />
        </inertial>
        <visual>
            <origin xyz="0 0 0.10908458525253449" rpy="0 0 0"/>
            <geometry>
                <box size="0.48710068889518043 0.3209158704775411 0.21816917050506898" />
            </geometry>
            <material name="Green">
                <color rgba="0 1.0 0 1.0"/>
            </material>
        </visual>
        <collision>
            <origin xyz="0 0 0.10908458525253449" rpy="0 0 0"/>
            <geometry>
                <box size="0.48710068889518043 0.3209158704775411 0.21816917050506898" />
            </geometry>
        </collision>
    </link>
    <joint name="3_10" type="revolute">
       <parent link="3"/>
       <child  link="10"/>
       <origin rpy="0 0 0" xyz="0.277912802664224 -0.22317973173102607 0" />
     <axis xyz="1 1 0"/>
       <limit effort="0.0" lower="-3.14159" upper="3.14159" velocity="0.0"/>
    </joint>
    <link name="10">
        <inertial>
            <origin xyz="0 -0.07898480749905441 0" rpy="0 0 0"/>
            <mass value="1" />
            <inertia ixx="100" ixy="0" ixz="0" iyy="100" iyz="0" izz="100" />
        </inertial>
        <visual>
            <origin xyz="0 -0.07898480749905441 0" rpy="0 0 0"/>
            <geometry>
                <box size="0.49626618069039163 0.15796961499810883 0.20490814565428492" />
            </geometry>
            <material name="Cyan">
                <color rgba="0 1.0 1.0 1.0"/>
            </material>
        </visual>
        <collision>
            <origin xyz="0 -0.07898480749905441 0" rpy="0 0 0"/>
            <geometry>
                <box size="0.49626618069039163 0.15796961499810883 0.20490814565428492" />
            </geometry>
        </collision>
    </link>
</robot>